#VRML_SIM R2019a utf8
WorldInfo {
  info [
    "Example use of a color Camera device."
  ]
  title "Camera"
}
Viewpoint {
  orientation 0.03709799000670551 -0.9673103756386023 -0.25086724839916463 3.5441702914952704
  position 1.3704314495798915 2.0861700979192377 -3.269999560439489
}
TexturedBackground {
}
Shape {
  appearance Appearance {
    material Material {
      diffuseColor 1 1 1
    }
  }
  geometry Cylinder {
    height 0.0001
  }
}
Shape {
  appearance Appearance {
    material Material {
      diffuseColor 1 1 1
    }
  }
  geometry Plane {
    size 10 10
  }
}
TexturedBackgroundLight {
  castShadows FALSE
}
CircleArena {
  wallThickness 0.06
  wallHeight 0.0001
  wallAppearance BrushedAluminium {
    colorOverride 0 0 0
  }
}
DirectionalLight {
  direction 1 -1 -1
  intensity 0.4
}
DEF KOSTAS Robot {
  translation -0.7 0.19996072895261152 0.4
  rotation -2.454757556084567e-05 -0.999999784870417 0.0006554819116711327 1.57
  children [
    Transform {
      translation 0 -0.03 0
      children [
        Shape {
          appearance PBRAppearance {
            baseColor 0 1 0
            roughness 1
            metalness 0
          }
          geometry DEF BODY Box {
            size 0.4 0.2 0.4
          }
        }
      ]
    }
    HingeJoint {
      jointParameters HingeJointParameters {
        position -18995.77604443276
        axis -1 0 0
        anchor 0.2 -0.14 0.1
      }
      device [
        RotationalMotor {
          name "right wheel motor K back"
          consumptionFactor 70
        }
        PositionSensor {
          name "right wheel sensor K back"
        }
      ]
      endPoint Solid {
        translation 0.2 -0.14 0.1
        rotation -0.9999999999999997 2.454322286910022e-08 -1.4751370197745582e-08 4.2239545768830835
        children [
          DEF WHEEL_FRONT Transform {
            rotation 0 0 1 1.57
            children [
              Shape {
                appearance PBRAppearance {
                  baseColor 0 1 0
                  roughness 1
                  metalness 0
                }
                geometry Cylinder {
                  height 0.04
                  radius 0.06
                }
              }
            ]
          }
        ]
        name "right wheel K back"
        boundingObject USE WHEEL_FRONT
        physics DEF PHYSICS_WHEEL_NEW Physics {
          density -1
          mass 0.05
        }
      }
    }
    HingeJoint {
      jointParameters HingeJointParameters {
        position 19131.45113338754
        axis -1 0 0
        anchor 0.2 -0.14 -0.1
      }
      device [
        RotationalMotor {
          name "right wheel motor K front"
          consumptionFactor 70
        }
        PositionSensor {
          name "right wheel sensor K front"
        }
      ]
      endPoint Solid {
        translation 0.2 -0.14 -0.1
        rotation -1 0 0 5.082689421810894
        children [
          USE WHEEL_FRONT
        ]
        name "right wheel K front"
        boundingObject USE WHEEL_FRONT
        physics USE PHYSICS_WHEEL_NEW
      }
    }
    HingeJoint {
      jointParameters HingeJointParameters {
        position 19004.223950677486
        axis -1 0 0
        anchor -0.2 -0.14 0.1
      }
      device [
        RotationalMotor {
          name "left wheel motor K back"
          consumptionFactor 70
        }
        PositionSensor {
          name "left wheel sensor K back"
        }
      ]
      endPoint Solid {
        translation -0.2 -0.14 0.1
        rotation -1 0 0 4.223950677485843
        children [
          USE WHEEL_FRONT
        ]
        name "left wheel K back"
        boundingObject USE WHEEL_FRONT
        physics DEF PHYSICS_WHEEL_NEW Physics {
          density -1
          mass 0.05
        }
      }
    }
    HingeJoint {
      jointParameters HingeJointParameters {
        position -18817.352297818798
        axis -1 0 0
        anchor -0.2 -0.14 -0.1
      }
      device [
        RotationalMotor {
          name "left wheel motor K front"
          consumptionFactor 70
        }
        PositionSensor {
          name "left wheel sensor K front"
        }
      ]
      endPoint Solid {
        translation -0.20000000000000004 -0.14089743290121454 -0.10192960690069335
        rotation 1 0 0 5.847857034185117
        children [
          USE WHEEL_FRONT
        ]
        name "left wheel K front"
        boundingObject USE WHEEL_FRONT
        physics USE PHYSICS_WHEEL_NEW
      }
    }
    DistanceSensor {
      translation -0.1 0.02 -0.2
      rotation 0 1 0 1.5707996938995747
      children [
        DEF SENSOR Transform {
          rotation 0 0 1 1.57
          children [
            Shape {
              appearance PBRAppearance {
                baseColor 0.975691 0.981481 0.0252992
                roughness 1
                metalness 0
              }
              geometry Cylinder {
                height 0.016
                radius 0.032
              }
            }
          ]
        }
      ]
      name "ds0_k"
    }
    DistanceSensor {
      translation 0.1 0.02 -0.19999999999999998
      rotation 0 1 0 1.5708003061004252
      children [
        DEF SENSOR Transform {
          rotation 0 0 1 1.57
          children [
            Shape {
              appearance PBRAppearance {
                baseColor 0.975691 0.981481 0.0252992
                roughness 1
                metalness 0
              }
              geometry Cylinder {
                height 0.016
                radius 0.032
              }
            }
          ]
        }
      ]
      name "ds1_k"
    }
    Camera {
      translation 0 0.098 -0.2
      rotation 1.1144712396872027e-06 0.768221328583247 -0.6401843408804598 6.197284940292589
      children [
        Transform {
          translation 0 0.01 0.08
          rotation 0.9987503463604381 0 -0.049977451364642024 4.691870306100426
          children [
            Shape {
              appearance PBRAppearance {
                roughness 1
                metalness 0
              }
              geometry Cylinder {
                height 0.15
                radius 0.04
              }
            }
          ]
        }
      ]
      name "camera K"
      fieldOfView 1.05
      width 80
      height 60
    }
  ]
  name "kostas"
  boundingObject Transform {
    translation 0 -0.03 0
    children [
      USE BODY
    ]
  }
  physics Physics {
    density -1
    mass 0.5
  }
  controller "cameraK"
  supervisor TRUE
}
DEF ANTONIA Robot {
  translation 0.5 0 0.5
  rotation 0 -1 0 5
  children [
    Transform {
      translation 0 0.17 0
      children [
        Shape {
          appearance PBRAppearance {
            baseColor 0 0 1
            roughness 1
            metalness 0
          }
          geometry DEF BODY Cylinder {
            height 0.32
            radius 0.18
          }
        }
      ]
    }
    HingeJoint {
      jointParameters HingeJointParameters {
        position -18328.894831014244
        axis -1 0 0
        anchor -0.17 0.1 0
      }
      device [
        RotationalMotor {
          name "left wheel motor A"
          consumptionFactor 70
        }
        PositionSensor {
          name "left wheel sensor A"
        }
      ]
      endPoint Solid {
        translation -0.17 0.09889061041792273 -0.0020747986623937532
        rotation -0.9989137083553896 -0.008773988189223429 0.045764837931960706 0.4648702863732346
        children [
          DEF WHEEL Transform {
            rotation 0 0 1 1.57
            children [
              Shape {
                appearance PBRAppearance {
                  baseColor 0 0 1
                  roughness 1
                  metalness 0
                }
                geometry Cylinder {
                  height 0.04
                  radius 0.1
                }
              }
            ]
          }
        ]
        name "left wheel A"
        boundingObject USE WHEEL
        physics DEF PHYSICS_WHEEL Physics {
          density -1
          mass 0.05
        }
      }
    }
    HingeJoint {
      jointParameters HingeJointParameters {
        position 19873.10181191758
        axis -1 0 0
        anchor 0.17 0.1 0
      }
      device [
        RotationalMotor {
          name "right wheel motor A"
          consumptionFactor 70
        }
        PositionSensor {
          name "right wheel sensor A"
        }
      ]
      endPoint Solid {
        translation 0.17 0.09305352185265944 -0.0036441335363043147
        rotation 0.9997796792963155 -0.01834563554870327 -0.010199535404660521 5.209625154620606
        children [
          USE WHEEL
        ]
        name "right wheel A"
        boundingObject USE WHEEL
        physics USE PHYSICS_WHEEL
      }
    }
    DistanceSensor {
      translation -0.1 0.25 -0.15
      rotation 0 1 0 2.07
      children [
        DEF SENSOR Transform {
          rotation 0 0 1 1.57
          children [
            Shape {
              appearance PBRAppearance {
                baseColor 0.975691 0.981481 0.0252992
                roughness 1
                metalness 0
              }
              geometry Cylinder {
                height 0.016
                radius 0.032
              }
            }
          ]
        }
      ]
      name "ds0"
      lookupTable [
        0 1024 0
        0.05 1024 0
        0.15 0 0
      ]
      numberOfRays 2
      aperture 1
    }
    DistanceSensor {
      translation 0.1 0.25 -0.15
      rotation 0 1 0 1.07
      children [
        USE SENSOR
      ]
      name "ds1"
      lookupTable [
        0 1024 0
        0.05 1024 0
        0.15 0 0
      ]
      numberOfRays 2
      aperture 1
    }
    DEF SMILE Transform {
      translation 0 0.1 -0.15
      rotation 0.7745972408364944 0.44721228048294853 0.4472139204829502 1.8234794
      children [
        Shape {
          appearance PBRAppearance {
            baseColor 0.721569 0.290196 0.290196
            roughness 1
            metalness 0
          }
          geometry Cylinder {
            height 0.072
            radius 0.036
            subdivision 3
          }
        }
      ]
    }
    Camera {
      translation 0 0.365 -0.11
      rotation 0 0 -1 0
      children [
        Transform {
          translation 0 0 0.015
          rotation 1 0 0 1.57
          children [
            Shape {
              appearance PBRAppearance {
                roughness 1
                metalness 0
              }
              geometry Cylinder {
                height 0.14
                radius 0.04
              }
            }
          ]
        }
      ]
      name "camera A"
      fieldOfView 1.047
      width 80
      height 60
      antiAliasing TRUE
      noise 0.04
    }
  ]
  name "antonia"
  boundingObject Transform {
    translation 0 0.17 0
    children [
      USE BODY
    ]
  }
  physics Physics {
    density -1
    mass 0.5
  }
  controller "cameraA"
  supervisor TRUE
}
