#VRML_SIM R2019a utf8
WorldInfo {
  info [
    "Example use of a color Camera device."
  ]
  title "Camera"
}
Viewpoint {
  orientation -0.10936636199459548 -0.9223747672042418 -0.3704912788298635 2.6884813930945937
  position -1.2720997545388721 2.3932563051195395 -2.4850400302596913
}
TexturedBackground {
}
Shape {
  appearance Appearance {
    material Material {
      diffuseColor 1 1 1
    }
  }
  geometry Cylinder {
    height 0.0001
  }
}
Shape {
  appearance Appearance {
    material Material {
      diffuseColor 1 1 1
    }
  }
  geometry Plane {
    size 10 10
  }
}
TexturedBackgroundLight {
  castShadows FALSE
}
CircleArena {
  wallThickness 0.06
  wallHeight 0.0001
  wallAppearance BrushedAluminium {
    colorOverride 0 0 0
  }
}
DirectionalLight {
  direction 1 -1 -1
  intensity 0.4
}
DEF KOSTAS Robot {
  translation -0.7 0 0.4
  rotation 0 -1 0 1.57
  children [
    Transform {
      translation 0 0.135 0
      children [
        Shape {
          appearance PBRAppearance {
            baseColor 0 1 0
            roughness 1
            metalness 0
          }
          geometry DEF BODY Cylinder {
            height 0.24
            radius 0.208
          }
        }
      ]
    }
    HingeJoint {
      jointParameters HingeJointParameters {
        position -18866
        axis -1 0 0
        anchor -0.21 0.109 0
      }
      device [
        RotationalMotor {
          name "left wheel motor K"
          consumptionFactor 70
        }
        PositionSensor {
          name "left wheel sensor K"
        }
      ]
      endPoint Solid {
        translation -0.20999999999999996 0.1083606455220222 -0.00041135140200985077
        rotation -0.9999374178645228 0.011084459113758058 0.001514965539610692 3.713116844463843
        children [
          DEF WHEEL Transform {
            rotation 0 0 1 1.57
            children [
              Shape {
                appearance PBRAppearance {
                  baseColor 0 1 0
                  roughness 1
                  metalness 0
                }
                geometry Cylinder {
                  height 0.04
                  radius 0.1
                }
              }
            ]
          }
        ]
        name "left wheel K"
        boundingObject USE WHEEL
        physics DEF PHYSICS_WHEEL Physics {
          density -1
          mass 0.05
        }
      }
    }
    HingeJoint {
      jointParameters HingeJointParameters {
        position 19134.3
        axis -1 0 0
        anchor 0.21 0.109 0
      }
      device [
        RotationalMotor {
          name "right wheel motor K"
          consumptionFactor 70
        }
        PositionSensor {
          name "right wheel sensor K"
        }
      ]
      endPoint Solid {
        translation 0.20999999999999994 0.1088072870063658 4.4960622627003953e-05
        rotation 0.9999378777646389 -0.007768793515326881 0.007992900528977063 2.595796726389603
        children [
          USE WHEEL
        ]
        name "right wheel K"
        boundingObject USE WHEEL
        physics USE PHYSICS_WHEEL
      }
    }
    DistanceSensor {
      translation -0.08 0.2 -0.2
      rotation 0 1 0 2.07
      children [
        DEF SENSOR Transform {
          rotation 0 0 1 1.57
          children [
            Shape {
              appearance PBRAppearance {
                baseColor 0.975691 0.981481 0.0252992
                roughness 1
                metalness 0
              }
              geometry Cylinder {
                height 0.016
                radius 0.032
              }
            }
          ]
        }
      ]
      name "ds0_k"
      lookupTable [
        0 1024 0
        0.05 1024 0
        0.15 0 0
      ]
      numberOfRays 2
      aperture 1
    }
    DistanceSensor {
      translation 0.08 0.2 -0.2
      rotation 0 1 0 1.07
      children [
        USE SENSOR
      ]
      name "ds1_k"
      lookupTable [
        0 1024 0
        0.05 1024 0
        0.15 0 0
      ]
      numberOfRays 2
      aperture 1
    }
    DEF SMILE Transform {
      translation 0 0.08 -0.19
      rotation 0.7745972408364944 0.44721228048294853 0.4472139204829502 1.8234794
      children [
        Shape {
          appearance PBRAppearance {
            baseColor 0.721569 0.290196 0.290196
            roughness 1
            metalness 0
          }
          geometry Cylinder {
            height 0.072
            radius 0.036
            subdivision 3
          }
        }
      ]
    }
    Camera {
      translation 0 0.3 -0.15
      rotation 0 0 -1 0
      children [
        Transform {
          translation 0 0 -0.015
          rotation 1 0 0 1.57
          children [
            Shape {
              appearance PBRAppearance {
                roughness 1
                metalness 0
              }
              geometry Cylinder {
                height 0.12
                radius 0.04
              }
            }
          ]
        }
      ]
      name "camera K"
      fieldOfView 1.047
      width 80
      height 60
      antiAliasing TRUE
      noise 0.04
    }
  ]
  name "kostas"
  boundingObject Transform {
    translation 0 0.135 0
    children [
      USE BODY
    ]
  }
  physics Physics {
    density -1
    mass 0.5
  }
  controller "cameraK"
  supervisor TRUE
}
DEF ANTONIA Robot {
  translation 0.5 0 0.5
  rotation 0 -1 0 5
  children [
    Transform {
      translation 0 0.17 0
      children [
        Shape {
          appearance PBRAppearance {
            baseColor 0 0 1
            roughness 1
            metalness 0
          }
          geometry DEF BODY Cylinder {
            height 0.32
            radius 0.18
          }
        }
      ]
    }
    HingeJoint {
      jointParameters HingeJointParameters {
        position -18436
        axis -1 0 0
        anchor -0.17 0.1 0
      }
      device [
        RotationalMotor {
          name "left wheel motor A"
          consumptionFactor 70
        }
        PositionSensor {
          name "left wheel sensor A"
        }
      ]
      endPoint Solid {
        translation -0.17 0.0995325764182377 -0.002305872921369475
        rotation 0.9924005202512072 0.040446772238359255 -0.11621215952141845 6.10849995178862
        children [
          DEF WHEEL Transform {
            rotation 0 0 1 1.57
            children [
              Shape {
                appearance PBRAppearance {
                  baseColor 0 0 1
                  roughness 1
                  metalness 0
                }
                geometry Cylinder {
                  height 0.04
                  radius 0.1
                }
              }
            ]
          }
        ]
        name "left wheel A"
        boundingObject USE WHEEL
        physics DEF PHYSICS_WHEEL Physics {
          density -1
          mass 0.05
        }
      }
    }
    HingeJoint {
      jointParameters HingeJointParameters {
        position 19765.2
        axis -1 0 0
        anchor 0.17 0.1 0
      }
      device [
        RotationalMotor {
          name "right wheel motor A"
          consumptionFactor 70
        }
        PositionSensor {
          name "right wheel sensor A"
        }
      ]
      endPoint Solid {
        translation 0.17 0.1 -0.00784431436659048
        rotation 0.5542291922669046 0.41326297065310674 0.7225259300026154 0.025791939667451913
        children [
          USE WHEEL
        ]
        name "right wheel A"
        boundingObject USE WHEEL
        physics USE PHYSICS_WHEEL
      }
    }
    DistanceSensor {
      translation -0.1 0.25 -0.15
      rotation 0 1 0 2.07
      children [
        DEF SENSOR Transform {
          rotation 0 0 1 1.57
          children [
            Shape {
              appearance PBRAppearance {
                baseColor 0.975691 0.981481 0.0252992
                roughness 1
                metalness 0
              }
              geometry Cylinder {
                height 0.016
                radius 0.032
              }
            }
          ]
        }
      ]
      name "ds0"
      lookupTable [
        0 1024 0
        0.05 1024 0
        0.15 0 0
      ]
      numberOfRays 2
      aperture 1
    }
    DistanceSensor {
      translation 0.1 0.25 -0.15
      rotation 0 1 0 1.07
      children [
        USE SENSOR
      ]
      name "ds1"
      lookupTable [
        0 1024 0
        0.05 1024 0
        0.15 0 0
      ]
      numberOfRays 2
      aperture 1
    }
    DEF SMILE Transform {
      translation 0 0.1 -0.15
      rotation 0.7745972408364944 0.44721228048294853 0.4472139204829502 1.8234794
      children [
        Shape {
          appearance PBRAppearance {
            baseColor 0.721569 0.290196 0.290196
            roughness 1
            metalness 0
          }
          geometry Cylinder {
            height 0.072
            radius 0.036
            subdivision 3
          }
        }
      ]
    }
    Camera {
      translation 0 0.365 -0.11
      rotation 0 0 -1 0
      children [
        Transform {
          translation 0 0 0.015
          rotation 1 0 0 1.57
          children [
            Shape {
              appearance PBRAppearance {
                roughness 1
                metalness 0
              }
              geometry Cylinder {
                height 0.14
                radius 0.04
              }
            }
          ]
        }
      ]
      name "camera A"
      fieldOfView 1.047
      width 80
      height 60
      antiAliasing TRUE
      noise 0.04
    }
  ]
  name "antonia"
  boundingObject Transform {
    translation 0 0.17 0
    children [
      USE BODY
    ]
  }
  physics Physics {
    density -1
    mass 0.5
  }
  controller "cameraA"
  supervisor TRUE
}
